Workbook

Sheet P2 Indice
A1: PROYECTO 2 - SEGUNDO PARCIAL DE MECANISMOS - DOSIFICADOR DE TOLVA
A2: Universidad Rafael Landivar - Ing. Eli Saul De Paz Aldana - Entrega: jueves 1 de octubre de 2026
A4: COMO USAR ESTE LIBRO
A5: Ejemplo | B5: Celda amarilla con texto azul | C5: Dato que puedes cambiar (entrada).
A6: Ejemplo | B6: Celda gris | C6: Formula: se calcula sola, no la edites.
A7: Ejemplo | B7: Texto verde | C7: Vinculo a otra hoja del libro.
A8: Ejemplo | B8: Celda lila | C8: Valor importado de MATLAB o Inventor (no es formula; la fuente esta indicada en la hoja).
A9: Ejemplo | B9: Celda verde clara | C9: Verificacion automatica (CUMPLE / VALIDADO).
A11: HOJAS DEL PROYECTO
A12: Inciso | B12: Hoja | C12: Que contiene
A13: a) | B13: P2 a) Datos y Sintesis | C13: Datos del mecanismo (unica hoja con medidas), sintesis de numero (Gruebler), sintesis dimensional paso a paso, puntos muertos, carrera, relacion de tiempos, angulo de transmision y verificacion de requisitos.
A14: e) | B14: P2 Calculadora M-C | C14: Calculadora de una posicion, paso a paso (abierta y cruzada). Por defecto θ2 = 36° = ejemplo resuelto del informe.
A15: e) | B15: P2 e) 10 posiciones | C15: Los 10 calculos de posicion, velocidad y aceleracion + comprobacion contra la Calculadora de Mecanismos (MATLAB).
A16: f) | B16: P2 f) Validacion | C16: Tabla de % de error por posicion: analitico (Excel) vs simulacion MATLAB vs Inventor.
A17: f) | B17: P2 Graficas | C17: Graficas de ω3 y α3 (y del bloque) en funcion de θ2, con los 10 puntos y la simulacion.
A18: f) | B18: P2 Curva | C18: Vuelta completa cada 0.5° (datos de las graficas).
A19: g) | B19: P2 g) Contraste | C19: Contraste experimental: escribir lo medido en el modelo; calcula diferencias y estima holguras, tolerancias, friccion y par del motor.
A20: d) | B20: (lo hace el grupo) | C20: Las 3 mediciones de rpm se escriben en la hoja g) (seccion 1) y en P2_2_Analisis_Validacion.m (rpm_medidas).
A21: — | B21: Fila 1 … Tabla | C21: Hojas originales de la calculadora de cuatro barras (sin cambios).
A23: Mecanismo: manivela-corredera descentrada (inversion del cuatro barras con una junta prismatica): a = 35 mm, b = 132 mm, c = −20 mm, 30 rpm de diseno.
A24: Las hojas originales "Calculadora" y "Tabla" resuelven el cuatro barras con pasadores (Freudenstein); el dosificador usa las hojas P2.

Sheet P2 a) Datos y Sintesis
A1: PROYECTO 2 - DOSIFICADOR DE TOLVA (MANIVELA-CORREDERA DESCENTRADA)
A2: Segundo examen parcial de Mecanismos. Edita SOLO las celdas amarillas (columna C). Todas las hojas que empiezan con "P2" se recalculan solas con estos datos.
A4: 1. DATOS DEL MECANISMO - edita SOLO las celdas amarillas
A5: Parametro | B5: Simbolo | C5: Valor | D5: Unidad | F5: Descripcion
A6: Manivela (eslabon 2) | B6: a | C6: 35 | D6: mm | F6: O2-A. La mueve el motor (rueda naranja en Inventor).
A7: Biela (acoplador, eslabon 3) | B7: b | C7: 132 | D7: mm | F7: A-B (acoplador magenta en Inventor).
A8: Descentrado de la corredera | B8: c | C8: -20 | D8: mm | F8: Negativo: el eje del bloque pasa 20 mm por debajo de O2.
A9: Velocidad del motor (diseno) | B9: n | C9: 30 | D9: rpm | F9: Se usa en los calculos hasta que el grupo mida la real (inciso d).
A10: Sentido de giro | B10: s | C10: 1 | D10: - | F10: +1 antihorario (visto desde el lado de la biela), -1 horario.
A11: Aceleracion angular de entrada | B11: α2 | C11: 0 | D11: rad/s² | F11: 0 = el motor gira a velocidad constante.
A12: Velocidad angular de entrada | B12: ω2 | C12: =C10*C9*2*PI()/60 -> 3.1415927 | D12: rad/s | F12: ω2 = s·n·2π/60
A14: 2. SINTESIS DE NUMERO (Gruebler) - automatico
A15: Concepto | B15: Simbolo | C15: Valor | D15: Unidad | F15: Notas
A16: Eslabones (bancada, manivela, biela, bloque) | B16: L | C16: 4
A17: Juntas completas (3 pasadores + 1 corredera) | B17: J1 | C17: 4
A18: Semijuntas | B18: J2 | C18: 0
A19: Grados de libertad | B19: M | C19: =3*(C16-1)-2*C17-C18 -> 1 | F19: M = 3(L-1) - 2J1 - J2. M = 1: un solo motor define todo el movimiento.
A21: 3. SINTESIS DIMENSIONAL PASO A PASO - automatico
A22: Paso / requisito | B22: Simbolo | C22: Valor | D22: Unidad | F22: Expresion y criterio
A23: R1. Carrera deseada del bloque (dosis) | B23: S obj | C23: 70 | D23: mm | F23: Requisito de diseno: tamano de la dosis.
A24: Paso 1. Manivela sugerida (corredera centrada) | B24: a ≈ S/2 | C24: =C23/2 -> 35 | D24: mm | F24: En la manivela-corredera centrada la carrera vale 2a.
A25: Paso 2. Biela minima para vuelta completa | B25: b min | C25: =P2_a+ABS(P2_c) -> 55 | D25: mm | F25: R2: la manivela gira completa si b ≥ a + |c|.
A26: Paso 3. Biela minima para μ ≥ 45° | B26: b μ45 | C26: =(P2_a+ABS(P2_c))/SIN(RADIANS(45)) -> 77.781746 | D26: mm | F26: R3: el peor μ ocurre en θ2 = 90°: sen(90°-μ) = (a+|c|)/b.
A27: Paso 4. Relacion biela/manivela elegida | B27: b/a | C27: =P2_b/P2_a -> 3.7714286 | D27: - | F27: R5: biela larga (b/a > 3): menos aceleracion y el bloque no choca con la manivela.
A29: 4. RESULTADOS DE LA SINTESIS (inciso a) - automatico
A30: Parametro | B30: Simbolo | C30: Valor | D30: Unidad | F30: Expresion
A31: Posicion en el punto muerto interior | B31: d min | C31: =SQRT((P2_b-P2_a)^2-P2_c^2) -> 94.915752 | D31: mm | F31: d min = √((b−a)² − c²)
A32: θ2 en el punto muerto interior | B32: θ2 int | C32: =MOD(180+DEGREES(ASIN(P2_c/(P2_b-P2_a))),360) -> 168.10109 | D32: ° | F32: θ2 = 180° + asen(c/(b−a))
A33: Posicion en el punto muerto exterior | B33: d max | C33: =SQRT((P2_a+P2_b)^2-P2_c^2) -> 165.79807 | D33: mm | F33: d max = √((a+b)² − c²)
A34: θ2 en el punto muerto exterior | B34: θ2 ext | C34: =MOD(DEGREES(ASIN(P2_c/(P2_a+P2_b))),360) -> 353.12172 | D34: ° | F34: θ2 = asen(c/(a+b))
A35: Carrera del bloque | B35: S | C35: =C33-C31 -> 70.882318 | D35: mm | F35: S = d max − d min
A36: Angulo de manivela en el avance | B36: β av | C36: =IF(P2_sentido>0,MOD(C34-C32,360),360-MOD(C34-C32,360)) -> 185.02063 | D36: ° | F36: Avance: el bloque se aleja de O2 y empuja el material.
A37: Angulo de manivela en el retorno | B37: β ret | C37: =360-C36 -> 174.97937 | D37: ° | F37: β ret = 360° − β av
A38: Relacion de tiempos | B38: Q | C38: =C36/C37 -> 1.0573854 | D38: - | F38: Q = β av / β ret (≠ 1 por el descentrado)
A39: Angulo de transmision minimo | B39: μ min | C39: =90-DEGREES(ASIN((P2_a+ABS(P2_c))/P2_b)) -> 65.375682 | D39: ° | F39: μ min = 90° − asen((a+|c|)/b)
A40: θ2 donde ocurre μ min | B40: θ2 μmin | C40: =IF(P2_c>0,270,90) -> 90 | D40: ° | F40: Manivela perpendicular a la corredera.
A42: 5. VERIFICACION DE LOS REQUISITOS
A43: Requisito | C43: Resultado | F43: Criterio
A44: R1. Carrera cercana a la deseada | C44: =IF(ABS(C35-C23)<=0.05*C23,"CUMPLE ("&FIXED(C35,2)&" mm)","REVISAR ("&FIXED(C35,2)&" mm)") -> CUMPLE (70.88 mm) | F44: |S − S obj| ≤ 5 %
A45: R2. La manivela da vuelta completa | C45: =IF(P2_b>=P2_a+ABS(P2_c),"CUMPLE","NO CUMPLE") -> CUMPLE | F45: b ≥ a + |c|
...

Sheet P2 Calculadora M-C
A1: CALCULADORA MANIVELA-CORREDERA (una posicion, paso a paso)
A2: Mismas ecuaciones que la Calculadora_Mecanismos.m del grupo (mecanismo 3). Las medidas y ω2 vienen de la hoja "P2 a) Datos y Sintesis"; aqui solo se cambia θ2 (celda amarilla). Por defecto θ2 = 36°: es el ejemplo resuelto del informe.
A4: 1. DATOS
A5: Parametro | B5: Simbolo | C5: Valor | D5: Unidad | F5: Origen
A6: Manivela | B6: a | C6: =P2_a -> 35 | D6: mm | F6: Hoja P2 a) Datos y Sintesis
A7: Biela | B7: b | C7: =P2_b -> 132 | D7: mm | F7: Hoja P2 a) Datos y Sintesis
A8: Descentrado | B8: c | C8: =P2_c -> -20 | D8: mm | F8: Hoja P2 a) Datos y Sintesis
A9: Velocidad angular de entrada | B9: ω2 | C9: =P2_w2 -> 3.1415927 | D9: rad/s | F9: Hoja P2 a) Datos y Sintesis
A10: Aceleracion angular de entrada | B10: α2 | C10: =P2_al2 -> 0 | D10: rad/s² | F10: Hoja P2 a) Datos y Sintesis
A11: Angulo de la manivela | B11: θ2 | C11: 36 | D11: grados | F11: Escribe cualquier angulo de 0 a 360.
A13: 2. POSICION
A14: Variable | B14: Simbolo | C14: Solucion ABIERTA | D14: Solucion CRUZADA | E14: Unidad | F14: Expresion (Norton)
A15: Seno del angulo de la biela (auxiliar) | B15: s | C15: =(C6*SIN(RADIANS($C$11))-C8)/C7 -> 0.3073673 | D15: =(C6*SIN(RADIANS($C$11))-C8)/C7 -> 0.3073673 | E15: - | F15: s = (a·sen θ2 − c)/b
A16: Angulo de la biela | B16: θ3 | C16: =180-DEGREES(ASIN(C15)) -> 162.09936 | D16: =MOD(DEGREES(ASIN(D15)),360) -> 17.900643 | E16: ° | F16: θ3 = 180° − asen(s) (abierta); θ3 = asen(s) (cruzada)
A17: Posicion del bloque | B17: d | C17: =C6*COS(RADIANS($C$11))-C7*COS(RADIANS(C16)) -> 153.9256 | D17: =C6*COS(RADIANS($C$11))-C7*COS(RADIANS(D16)) -> -97.294411 | E17: mm | F17: d = a·cos θ2 − b·cos θ3
A18: Punto A - x | B18: Ax | C18: =C6*COS(RADIANS($C$11)) -> 28.315595 | D18: =C6*COS(RADIANS($C$11)) -> 28.315595 | E18: mm | F18: Ax = a·cos θ2
A19: Punto A - y | B19: Ay | C19: =C6*SIN(RADIANS($C$11)) -> 20.572484 | D19: =C6*SIN(RADIANS($C$11)) -> 20.572484 | E19: mm | F19: Ay = a·sen θ2
A20: Punto B - x | B20: Bx | C20: =C17 -> 153.9256 | D20: =D17 -> -97.294411 | E20: mm | F20: Bx = d
A21: Punto B - y | B21: By | C21: =C8 -> -20 | D21: =C8 -> -20 | E21: mm | F21: By = c
A22: Angulo de transmision | B22: μ | C22: =IF(MOD(ABS(C16-90),180)>90,180-MOD(ABS(C16-90),180),MOD(ABS(C16-90),180)) -> 72.099357 | D22: =IF(MOD(ABS(D16-90),180)>90,180-MOD(ABS(D16-90),180),MOD(ABS(D16-90),180)) -> 72.099357 | E22: ° | F22: Angulo agudo entre la biela y la normal a la corredera
A23: Comprobacion del lazo en x (debe ser 0) | B23: Rx | C23: =C6*COS(RADIANS($C$11))-C7*COS(RADIANS(C16))-C17 -> 0 | D23: =C6*COS(RADIANS($C$11))-C7*COS(RADIANS(D16))-D17 -> 0 | E23: mm | F23: a·cos θ2 − b·cos θ3 − d = 0
A24: Comprobacion del lazo en y (debe ser 0) | B24: Ry | C24: =C6*SIN(RADIANS($C$11))-C7*SIN(RADIANS(C16))-C8 -> 0 | D24: =C6*SIN(RADIANS($C$11))-C7*SIN(RADIANS(D16))-C8 -> 0 | E24: mm | F24: a·sen θ2 − b·sen θ3 − c = 0
A26: 3. VELOCIDAD
A27: Variable | B27: Simbolo | C27: Solucion ABIERTA | D27: Solucion CRUZADA | E27: Unidad | F27: Expresion
A28: Velocidad angular de la biela | B28: ω3 | C28: =C6*C9*COS(RADIANS($C$11))/(C7*COS(RADIANS(C16))) -> -0.7081925 | D28: =C6*C9*COS(RADIANS($C$11))/(C7*COS(RADIANS(D16))) -> 0.7081925 | E28: rad/s | F28: ω3 = a·ω2·cos θ2 / (b·cos θ3)
A29: Velocidad del bloque | B29: V_B | C29: =-C6*C9*SIN(RADIANS($C$11))+C7*C28*SIN(RADIANS(C16)) -> -93.363493 | D29: =-C6*C9*SIN(RADIANS($C$11))+C7*D28*SIN(RADIANS(D16)) -> -35.897235 | E29: mm/s | F29: V_B = −a·ω2·sen θ2 + b·ω3·sen θ3
A30: Velocidad de A - x | B30: VAx | C30: =-C6*C9*SIN(RADIANS($C$11)) -> -64.630364 | D30: =-C6*C9*SIN(RADIANS($C$11)) -> -64.630364 | E30: mm/s | F30: VAx = −a·ω2·sen θ2
A31: Velocidad de A - y | B31: VAy | C31: =C6*C9*COS(RADIANS($C$11)) -> 88.956065 | D31: =C6*C9*COS(RADIANS($C$11)) -> 88.956065 | E31: mm/s | F31: VAy = a·ω2·cos θ2
A32: Velocidad de A - magnitud | B32: |V_A| | C32: =SQRT(C30^2+C31^2) -> 109.95574 | D32: =SQRT(D30^2+D31^2) -> 109.95574 | E32: mm/s | F32: |V_A| = a·|ω2| (constante)
A33: Velocidad de B respecto de A | B33: |V_B/A| | C33: =ABS(C7*C28) -> 93.481411 | D33: =ABS(C7*D28) -> 93.481411 | E33: mm/s | F33: |V_B/A| = b·|ω3|
A35: 4. ACELERACION
A36: Variable | B36: Simbolo | C36: Solucion ABIERTA | D36: Solucion CRUZADA | E36: Unidad | F36: Expresion
A37: Aceleracion angular de la biela | B37: α3 | C37: =(C6*C10*COS(RADIANS($C$11))-C6*C9^2*SIN(RADIANS($C$11))+C7*C28^2*SIN(RADIANS(C16)))/(C7*COS(RADIANS(C16))) -> 1.4544517 | D37: =(C6*C10*COS(RADIANS($C$11))-C6*C9^2*SIN(RADIANS($C$11))+C7*D28^2*SIN(RADIANS(D16)))/(C7*COS(RADIANS(D16))) -> -1.4544517 | E37: rad/s² | F37: α3 = (a·α2·cos θ2 − a·ω2²·sen θ2 + b·ω3²·sen θ3) / (b·cos θ3)
A38: Aceleracion del bloque | B38: A_B | C38: =-C6*C10*SIN(RADIANS($C$11))-C6*C9^2*COS(RADIANS($C$11))+C7*C37*SIN(RADIANS(C16))+C7*C28^2*COS(RADIANS(C16)) -> -283.45102 | D38: =-C6*C10*SIN(RADIANS($C$11))-C6*C9^2*COS(RADIANS($C$11))+C7*D37*SIN(RADIANS(D16))+C7*D28^2*COS(RADIANS(D16)) -> -275.47642 | E38: mm/s² | F38: A_B = −a·α2·sen θ2 − a·ω2²·cos θ2 + b·α3·sen θ3 + b·ω3²·cos θ3
A39: Aceleracion de A - x | B39: AAx | C39: =-C6*C9^2*COS(RADIANS($C$11))-C6*C10*SIN(RADIANS($C$11)) -> -279.46372 | D39: =-C6*C9^2*COS(RADIANS($C$11))-C6*C10*SIN(RADIANS($C$11)) -> -279.46372 | E39: mm/s² | F39: AAx = −a·ω2²·cos θ2 − a·α2·sen θ2
A40: Aceleracion de A - y | B40: AAy | C40: =-C6*C9^2*SIN(RADIANS($C$11))+C6*C10*COS(RADIANS($C$11)) -> -203.04228 | D40: =-C6*C9^2*SIN(RADIANS($C$11))+C6*C10*COS(RADIANS($C$11)) -> -203.04228 | E40: mm/s² | F40: AAy = −a·ω2²·sen θ2 + a·α2·cos θ2
A41: Aceleracion de A - magnitud | B41: |A_A| | C41: =SQRT(C39^2+C40^2) -> 345.43615 | D41: =SQRT(D39^2+D40^2) -> 345.43615 | E41: mm/s² | F41: |A_A| = a·ω2² (si α2 = 0)
A43: Signos: ω y α positivos = antihorario. V_B < 0: el bloque se acerca a O2 (retorno). La solucion ABIERTA es la del dosificador (bloque a la derecha de O2).

Sheet P2 e) 10 posiciones
A1: INCISO e) - POSICION, VELOCIDAD Y ACELERACION EN 10 POSICIONES
A2: Ecuaciones cerradas de Norton para la manivela-corredera (solucion abierta). Los angulos θ2 (amarillo) se pueden cambiar; medidas y ω2 vienen de "P2 a) Datos y Sintesis".
A4: 1. RESULTADOS DE LAS 10 POSICIONES
A5: Pos | B5: θ2 (°) | C5: θ3 (°) | D5: d (mm) | E5: μ (°) | F5: ω3 (rad/s) | G5: V_B (mm/s) | H5: α3 (rad/s²) | I5: A_B (mm/s²) | J5: |V_A| (mm/s) | K5: |A_A| (mm/s²) | L5: Sentido del bloque
A6: 1 | B6: 0 | C6: =180-DEGREES(ASIN((P2_a*SIN(RADIANS($B6))-P2_c)/P2_b)) -> 171.28526 | D6: =P2_a*COS(RADIANS($B6))-P2_b*COS(RADIANS(C6)) -> 165.47605 | E6: =90-DEGREES(ASIN(ABS((P2_a*SIN(RADIANS($B6))-P2_c)/P2_b))) -> 81.285258 | F6: =P2_a*P2_w2*COS(RADIANS($B6))/(P2_b*COS(RADIANS(C6))) -> -0.84272739 | G6: =-P2_a*P2_w2*SIN(RADIANS($B6))+P2_b*F6*SIN(RADIANS(C6)) -> -16.854548 | H6: =(P2_a*P2_al2*COS(RADIANS($B6))-P2_a*P2_w2^2*SIN(RADIANS($B6))+P2_b*F6^2*SIN(RADIANS(C6)))/(P2_b*COS(RADIANS(C6))) -> -0.10886127 | I6: =-P2_a*P2_al2*SIN(RADIANS($B6))-P2_a*P2_w2^2*COS(RADIANS($B6))+P2_b*H6*SIN(RADIANS(C6))+P2_b*F6^2*COS(RADIANS(C6)) -> -440.2761 | J6: =SQRT((-P2_a*P2_w2*SIN(RADIANS($B6)))^2+(P2_a*P2_w2*COS(RADIANS($B6)))^2) -> 109.95574 | K6: =SQRT((-P2_a*P2_w2^2*COS(RADIANS($B6))-P2_a*P2_al2*SIN(RADIANS($B6)))^2+(-P2_a*P2_w2^2*SIN(RADIANS($B6))+P2_a*P2_al2*COS(RADIANS($B6)))^2) -> 345.43615 | L6: =IF(G6>0,"avanza (empuja)",IF(G6<0,"retorna","detenido")) -> retorna
A7: 2 | B7: 36 | C7: =180-DEGREES(ASIN((P2_a*SIN(RADIANS($B7))-P2_c)/P2_b)) -> 162.09936 | D7: =P2_a*COS(RADIANS($B7))-P2_b*COS(RADIANS(C7)) -> 153.9256 | E7: =90-DEGREES(ASIN(ABS((P2_a*SIN(RADIANS($B7))-P2_c)/P2_b))) -> 72.099357 | F7: =P2_a*P2_w2*COS(RADIANS($B7))/(P2_b*COS(RADIANS(C7))) -> -0.7081925 | G7: =-P2_a*P2_w2*SIN(RADIANS($B7))+P2_b*F7*SIN(RADIANS(C7)) -> -93.363493 | H7: =(P2_a*P2_al2*COS(RADIANS($B7))-P2_a*P2_w2^2*SIN(RADIANS($B7))+P2_b*F7^2*SIN(RADIANS(C7)))/(P2_b*COS(RADIANS(C7))) -> 1.4544517 | I7: =-P2_a*P2_al2*SIN(RADIANS($B7))-P2_a*P2_w2^2*COS(RADIANS($B7))+P2_b*H7*SIN(RADIANS(C7))+P2_b*F7^2*COS(RADIANS(C7)) -> -283.45102 | J7: =SQRT((-P2_a*P2_w2*SIN(RADIANS($B7)))^2+(P2_a*P2_w2*COS(RADIANS($B7)))^2) -> 109.95574 | K7: =SQRT((-P2_a*P2_w2^2*COS(RADIANS($B7))-P2_a*P2_al2*SIN(RADIANS($B7)))^2+(-P2_a*P2_w2^2*SIN(RADIANS($B7))+P2_a*P2_al2*COS(RADIANS($B7)))^2) -> 345.43615 | L7: =IF(G7>0,"avanza (empuja)",IF(G7<0,"retorna","detenido")) -> retorna
A8: 3 | B8: 72 | C8: =180-DEGREES(ASIN((P2_a*SIN(RADIANS($B8))-P2_c)/P2_b)) -> 156.19099 | D8: =P2_a*COS(RADIANS($B8))-P2_b*COS(RADIANS(C8)) -> 131.58189 | E8: =90-DEGREES(ASIN(ABS((P2_a*SIN(RADIANS($B8))-P2_c)/P2_b))) -> 66.190987 | F8: =P2_a*P2_w2*COS(RADIANS($B8))/(P2_b*COS(RADIANS(C8))) -> -0.28135494 | G8: =-P2_a*P2_w2*SIN(RADIANS($B8))+P2_b*F8*SIN(RADIANS(C8)) -> -119.56668 | H8: =(P2_a*P2_al2*COS(RADIANS($B8))-P2_a*P2_w2^2*SIN(RADIANS($B8))+P2_b*F8^2*SIN(RADIANS(C8)))/(P2_b*COS(RADIANS(C8))) -> 2.6854436 | I8: =-P2_a*P2_al2*SIN(RADIANS($B8))-P2_a*P2_w2^2*COS(RADIANS($B8))+P2_b*H8*SIN(RADIANS(C8))+P2_b*F8^2*COS(RADIANS(C8)) -> 26.793601 | J8: =SQRT((-P2_a*P2_w2*SIN(RADIANS($B8)))^2+(P2_a*P2_w2*COS(RADIANS($B8)))^2) -> 109.95574 | K8: =SQRT((-P2_a*P2_w2^2*COS(RADIANS($B8))-P2_a*P2_al2*SIN(RADIANS($B8)))^2+(-P2_a*P2_w2^2*SIN(RADIANS($B8))+P2_a*P2_al2*COS(RADIANS($B8)))^2) -> 345.43615 | L8: =IF(G8>0,"avanza (empuja)",IF(G8<0,"retorna","detenido")) -> retorna
A9: 4 | B9: 108 | C9: =180-DEGREES(ASIN((P2_a*SIN(RADIANS($B9))-P2_c)/P2_b)) -> 156.19099 | D9: =P2_a*COS(RADIANS($B9))-P2_b*COS(RADIANS(C9)) -> 109.9507 | E9: =90-DEGREES(ASIN(ABS((P2_a*SIN(RADIANS($B9))-P2_c)/P2_b))) -> 66.190987 | F9: =P2_a*P2_w2*COS(RADIANS($B9))/(P2_b*COS(RADIANS(C9))) -> 0.28135494 | G9: =-P2_a*P2_w2*SIN(RADIANS($B9))+P2_b*F9*SIN(RADIANS(C9)) -> -89.581571 | H9: =(P2_a*P2_al2*COS(RADIANS($B9))-P2_a*P2_w2^2*SIN(RADIANS($B9))+P2_b*F9^2*SIN(RADIANS(C9)))/(P2_b*COS(RADIANS(C9))) -> 2.6854436 | I9: =-P2_a*P2_al2*SIN(RADIANS($B9))-P2_a*P2_w2^2*COS(RADIANS($B9))+P2_b*H9*SIN(RADIANS(C9))+P2_b*F9^2*COS(RADIANS(C9)) -> 240.28489 | J9: =SQRT((-P2_a*P2_w2*SIN(RADIANS($B9)))^2+(P2_a*P2_w2*COS(RADIANS($B9)))^2) -> 109.95574 | K9: =SQRT((-P2_a*P2_w2^2*COS(RADIANS($B9))-P2_a*P2_al2*SIN(RADIANS($B9)))^2+(-P2_a*P2_w2^2*SIN(RADIANS($B9))+P2_a*P2_al2*COS(RADIANS($B9)))^2) -> 345.43615 | L9: =IF(G9>0,"avanza (empuja)",IF(G9<0,"retorna","detenido")) -> retorna
A10: 5 | B10: 144 | C10: =180-DEGREES(ASIN((P2_a*SIN(RADIANS($B10))-P2_c)/P2_b)) -> 162.09936 | D10: =P2_a*COS(RADIANS($B10))-P2_b*COS(RADIANS(C10)) -> 97.294411 | E10: =90-DEGREES(ASIN(ABS((P2_a*SIN(RADIANS($B10))-P2_c)/P2_b))) -> 72.099357 | F10: =P2_a*P2_w2*COS(RADIANS($B10))/(P2_b*COS(RADIANS(C10))) -> 0.7081925 | G10: =-P2_a*P2_w2*SIN(RADIANS($B10))+P2_b*F10*SIN(RADIANS(C10)) -> -35.897235 | H10: =(P2_a*P2_al2*COS(RADIANS($B10))-P2_a*P2_w2^2*SIN(RADIANS($B10))+P2_b*F10^2*SIN(RADIANS(C10)))/(P2_b*COS(RADIANS(C10))) -> 1.4544517 | I10: =-P2_a*P2_al2*SIN(RADIANS($B10))-P2_a*P2_w2^2*COS(RADIANS($B10))+P2_b*H10*SIN(RADIANS(C10))+P2_b*F10^2*COS(RADIANS(C10)) -> 275.47642 | J10: =SQRT((-P2_a*P2_w2*SIN(RADIANS($B10)))^2+(P2_a*P2_w2*COS(RADIANS($B10)))^2) -> 109.95574 | K10: =SQRT((-P2_a*P2_w2^2*COS(RADIANS($B10))-P2_a*P2_al2*SIN(RADIANS($B10)))^2+(-P2_a*P2_w2^2*SIN(RADIANS($B10))+P2_a*P2_al2*COS(RADIANS($B10)))^2) -> 345.43615 | L10: =IF(G10>0,"avanza (empuja)",IF(G10<0,"retorna","detenido")) -> retorna
A11: 6 | B11: 180 | C11: =180-DEGREES(ASIN((P2_a*SIN(RADIANS($B11))-P2_c)/P2_b)) -> 171.28526 | D11: =P2_a*COS(RADIANS($B11))-P2_b*COS(RADIANS(C11)) -> 95.476051 | E11: =90-DEGREES(ASIN(ABS((P2_a*SIN(RADIANS($B11))-P2_c)/P2_b))) -> 81.285258 | F11: =P2_a*P2_w2*COS(RADIANS($B11))/(P2_b*COS(RADIANS(C11))) -> 0.84272739 | G11: =-P2_a*P2_w2*SIN(RADIANS($B11))+P2_b*F11*SIN(RADIANS(C11)) -> 16.854548 | H11: =(P2_a*P2_al2*COS(RADIANS($B11))-P2_a*P2_w2^2*SIN(RADIANS($B11))+P2_b*F11^2*SIN(RADIANS(C11)))/(P2_b*COS(RADIANS(C11))) -> -0.10886127 | I11: =-P2_a*P2_al2*SIN(RADIANS($B11))-P2_a*P2_w2^2*COS(RADIANS($B11))+P2_b*H11*SIN(RADIANS(C11))+P2_b*F11^2*COS(RADIANS(C11)) -> 250.59621 | J11: =SQRT((-P2_a*P2_w2*SIN(RADIANS($B11)))^2+(P2_a*P2_w2*COS(RADIANS($B11)))^2) -> 109.95574 | K11: =SQRT((-P2_a*P2_w2^2*COS(RADIANS($B11))-P2_a*P2_al2*SIN(RADIANS($B11)))^2+(-P2_a*P2_w2^2*SIN(RADIANS($B11))+P2_a*P2_al2*COS(RADIANS($B11)))^2) -> 345.43615 | L11: =IF(G11>0,"avanza (empuja)",IF(G11<0,"retorna","detenido")) -> avanza (empuja)
A12: 7 | B12: 216 | C12: =180-DEGREES(ASIN((P2_a*SIN(RADIANS($B12))-P2_c)/P2_b)) -> 180.24849 | D12: =P2_a*COS(RADIANS($B12))-P2_b*COS(RADIANS(C12)) -> 103.68316 | E12: =90-DEGREES(ASIN(ABS((P2_a*SIN(RADIANS($B12))-P2_c)/P2_b))) -> 89.751507 | F12: =P2_a*P2_w2*COS(RADIANS($B12))/(P2_b*COS(RADIANS(C12))) -> 0.67391592 | G12: =-P2_a*P2_w2*SIN(RADIANS($B12))+P2_b*F12*SIN(RADIANS(C12)) -> 64.244558 | H12: =(P2_a*P2_al2*COS(RADIANS($B12))-P2_a*P2_w2^2*SIN(RADIANS($B12))+P2_b*F12^2*SIN(RADIANS(C12)))/(P2_b*COS(RADIANS(C12))) -> -1.5362438 | I12: =-P2_a*P2_al2*SIN(RADIANS($B12))-P2_a*P2_w2^2*COS(RADIANS($B12))+P2_b*H12*SIN(RADIANS(C12))+P2_b*F12^2*COS(RADIANS(C12)) -> 220.39429 | J12: =SQRT((-P2_a*P2_w2*SIN(RADIANS($B12)))^2+(P2_a*P2_w2*COS(RADIANS($B12)))^2) -> 109.95574 | K12: =SQRT((-P2_a*P2_w2^2*COS(RADIANS($B12))-P2_a*P2_al2*SIN(RADIANS($B12)))^2+(-P2_a*P2_w2^2*SIN(RADIANS($B12))+P2_a*P2_al2*COS(RADIANS($B12)))^2) -> 345.43615 | L12: =IF(G12>0,"avanza (empuja)",IF(G12<0,"retorna","detenido")) -> avanza (empuja)
A13: 8 | B13: 252 | C13: =180-DEGREES(ASIN((P2_a*SIN(RADIANS($B13))-P2_c)/P2_b)) -> 185.77712 | D13: =P2_a*COS(RADIANS($B13))-P2_b*COS(RADIANS(C13)) -> 120.51398 | E13: =90-DEGREES(ASIN(ABS((P2_a*SIN(RADIANS($B13))-P2_c)/P2_b))) -> 84.222884 | F13: =P2_a*P2_w2*COS(RADIANS($B13))/(P2_b*COS(RADIANS(C13))) -> 0.25872462 | G13: =-P2_a*P2_w2*SIN(RADIANS($B13))+P2_b*F13*SIN(RADIANS(C13)) -> 101.13646 | H13: =(P2_a*P2_al2*COS(RADIANS($B13))-P2_a*P2_w2^2*SIN(RADIANS($B13))+P2_b*F13^2*SIN(RADIANS(C13)))/(P2_b*COS(RADIANS(C13))) -> -2.4947915 | I13: =-P2_a*P2_al2*SIN(RADIANS($B13))-P2_a*P2_w2^2*COS(RADIANS($B13))+P2_b*H13*SIN(RADIANS(C13))+P2_b*F13^2*COS(RADIANS(C13)) -> 131.10289 | J13: =SQRT((-P2_a*P2_w2*SIN(RADIANS($B13)))^2+(P2_a*P2_w2*COS(RADIANS($B13)))^2) -> 109.95574 | K13: =SQRT((-P2_a*P2_w2^2*COS(RADIANS($B13))-P2_a*P2_al2*SIN(RADIANS($B13)))^2+(-P2_a*P2_w2^2*SIN(RADIANS($B13))+P2_a*P2_al2*COS(RADIANS($B13)))^2) -> 345.43615 | L13: =IF(G13>0,"avanza (empuja)",IF(G13<0,"retorna","detenido")) -> avanza (empuja)
A14: 9 | B14: 288 | C14: =180-DEGREES(ASIN((P2_a*SIN(RADIANS($B14))-P2_c)/P2_b)) -> 185.77712 | D14: =P2_a*COS(RADIANS($B14))-P2_b*COS(RADIANS(C14)) -> 142.14517 | E14: =90-DEGREES(ASIN(ABS((P2_a*SIN(RADIANS($B14))-P2_c)/P2_b))) -> 84.222884 | F14: =P2_a*P2_w2*COS(RADIANS($B14))/(P2_b*COS(RADIANS(C14))) -> -0.25872462 | G14: =-P2_a*P2_w2*SIN(RADIANS($B14))+P2_b*F14*SIN(RADIANS(C14)) -> 108.01179 | H14: =(P2_a*P2_al2*COS(RADIANS($B14))-P2_a*P2_w2^2*SIN(RADIANS($B14))+P2_b*F14^2*SIN(RADIANS(C14)))/(P2_b*COS(RADIANS(C14))) -> -2.4947915 | I14: =-P2_a*P2_al2*SIN(RADIANS($B14))-P2_a*P2_w2^2*COS(RADIANS($B14))+P2_b*H14*SIN(RADIANS(C14))+P2_b*F14^2*COS(RADIANS(C14)) -> -82.388397 | J14: =SQRT((-P2_a*P2_w2*SIN(RADIANS($B14)))^2+(P2_a*P2_w2*COS(RADIANS($B14)))^2) -> 109.95574 | K14: =SQRT((-P2_a*P2_w2^2*COS(RADIANS($B14))-P2_a*P2_al2*SIN(RADIANS($B14)))^2+(-P2_a*P2_w2^2*SIN(RADIANS($B14))+P2_a*P2_al2*COS(RADIANS($B14)))^2) -> 345.43615 | L14: =IF(G14>0,"avanza (empuja)",IF(G14<0,"retorna","detenido")) -> avanza (empuja)
A15: 10 | B15: 324 | C15: =180-DEGREES(ASIN((P2_a*SIN(RADIANS($B15))-P2_c)/P2_b)) -> 180.24849 | D15: =P2_a*COS(RADIANS($B15))-P2_b*COS(RADIANS(C15)) -> 160.31435 | E15: =90-DEGREES(ASIN(ABS((P2_a*SIN(RADIANS($B15))-P2_c)/P2_b))) -> 89.751507 | F15: =P2_a*P2_w2*COS(RADIANS($B15))/(P2_b*COS(RADIANS(C15))) -> -0.67391592 | G15: =-P2_a*P2_w2*SIN(RADIANS($B15))+P2_b*F15*SIN(RADIANS(C15)) -> 65.01617 | H15: =(P2_a*P2_al2*COS(RADIANS($B15))-P2_a*P2_w2^2*SIN(RADIANS($B15))+P2_b*F15^2*SIN(RADIANS(C15)))/(P2_b*COS(RADIANS(C15))) -> -1.5362438 | I15: =-P2_a*P2_al2*SIN(RADIANS($B15))-P2_a*P2_w2^2*COS(RADIANS($B15))+P2_b*H15*SIN(RADIANS(C15))+P2_b*F15^2*COS(RADIANS(C15)) -> -338.53315 | J15: =SQRT((-P2_a*P2_w2*SIN(RADIANS($B15)))^2+(P2_a*P2_w2*COS(RADIANS($B15)))^2) -> 109.95574 | K15: =SQRT((-P2_a*P2_w2^2*COS(RADIANS($B15))-P2_a*P2_al2*SIN(RADIANS($B15)))^2+(-P2_a*P2_w2^2*SIN(RADIANS($B15))+P2_a*P2_al2*COS(RADIANS($B15)))^2) -> 345.43615 | L15: =IF(G15>0,"avanza (empuja)",IF(G15<0,"retorna","detenido")) -> avanza (empuja)
A17: Extremos entre las 10 posiciones:
A18: max |V_B| (mm/s) | D18: =SUMPRODUCT(MAX(ABS(G6:G15))) -> 119.56668 | F18: En la vuelta completa (hoja P2 Curva): max |V_B| = | J18: =SUMPRODUCT(MAX(ABS('P2 Curva'!F6:F726))) -> 119.8018 | K18: ="en θ2 = "&FIXED(SUMPRODUCT((ABS('P2 Curva'!F6:F726)=J18)*'P2 Curva'!A6:A726)/SUMPRODUCT(--(ABS('P2 Curva'!F6:F726)=J18)),1)&"°" -> en θ2 = 69.0°
A19: max |A_B| (mm/s²) | D19: =SUMPRODUCT(MAX(ABS(I6:I15))) -> 440.2761 | F19: En la vuelta completa (hoja P2 Curva): max |A_B| = | J19: =SUMPRODUCT(MAX(ABS('P2 Curva'!H6:H726))) -> 441.48911 | K19: ="en θ2 = "&FIXED(SUMPRODUCT((ABS('P2 Curva'!H6:H726)=J19)*'P2 Curva'!A6:A726)/SUMPRODUCT(--(ABS('P2 Curva'!H6:H726)=J19)),1)&"°" -> en θ2 = 356.5°
A20: max |ω3| (rad/s) | D20: =SUMPRODUCT(MAX(ABS(F6:F15))) -> 0.84272739 | F20: En la vuelta completa (hoja P2 Curva): max |ω3| = | J20: =SUMPRODUCT(MAX(ABS('P2 Curva'!E6:E726))) -> 0.84349737
A21: max |α3| (rad/s²) | D21: =SUMPRODUCT(MAX(ABS(H6:H15))) -> 2.6854436 | F21: En la vuelta completa (hoja P2 Curva): max |α3| = | J21: =SUMPRODUCT(MAX(ABS('P2 Curva'!G6:G726))) -> 2.8787346
A23: 2. COMPROBACION CON LA CALCULADORA DE MECANISMOS DEL GRUPO (MATLAB, mecanismo 3, solucion Abierta)
A24: Valores que muestra la calculadora en pantalla (4 decimales) con a = 35, b = 132, c = −20, ω2 = 3.1416 rad/s (30 rpm), α2 = 0. Fuente: P2_1_Calculadora_10_posiciones.m (Resultados_MATLAB/calculadora_10pos.json y capturas). La diferencia solo es de redondeo mientras los datos de la hoja de Datos sean los de diseno.
A25: Pos | B25: θ2 (°) | C25: θ3 calc | D25: d calc | E25: μ calc | F25: ω3 calc | G25: V_B calc | H25: α3 calc | I25: A_B calc | J25: max |Excel − calc| | K25: Coinciden
A26: 1 | B26: 0 | C26: 171.2853 | D26: 165.4761 | E26: 81.2853 | F26: -0.8427 | G26: -16.8545 | H26: -0.1089 | I26: -440.2761 | J26: =MAX(ABS(C6-C26),ABS(D6-D26),ABS(E6-E26),ABS(F6-F26),ABS(G6-G26),ABS(H6-H26),ABS(I6-I26)) -> 4.8557599e-05 | K26: =IF(AND(B26=B6,J26<=0.00051),"SI (redondeo)","NO - revisar datos") -> SI (redondeo)
A27: 2 | B27: 36 | C27: 162.0994 | D27: 153.9256 | E27: 72.0994 | F27: -0.7082 | G27: -93.3635 | H27: 1.4545 | I27: -283.451 | J27: =MAX(ABS(C7-C27),ABS(D7-D27),ABS(E7-E27),ABS(F7-F27),ABS(G7-G27),ABS(H7-H27),ABS(I7-I27)) -> 4.8268693e-05 | K27: =IF(AND(B27=B7,J27<=0.00051),"SI (redondeo)","NO - revisar datos") -> SI (redondeo)
A28: 3 | B28: 72 | C28: 156.191 | D28: 131.5819 | E28: 66.191 | F28: -0.2814 | G28: -119.5667 | H28: 2.6854 | I28: 26.7936 | J28: =MAX(ABS(C8-C28),ABS(D8-D28),ABS(E8-E28),ABS(F8-F28),ABS(G8-G28),ABS(H8-H28),ABS(I8-I28)) -> 4.5063806e-05 | K28: =IF(AND(B28=B8,J28<=0.00051),"SI (redondeo)","NO - revisar datos") -> SI (redondeo)
A29: 4 | B29: 108 | C29: 156.191 | D29: 109.9507 | E29: 66.191 | F29: 0.2814 | G29: -89.5816 | H29: 2.6854 | I29: 240.2849 | J29: =MAX(ABS(C9-C29),ABS(D9-D29),ABS(E9-E29),ABS(F9-F29),ABS(G9-G29),ABS(H9-H29),ABS(I9-I29)) -> 4.5063806e-05 | K29: =IF(AND(B29=B9,J29<=0.00051),"SI (redondeo)","NO - revisar datos") -> SI (redondeo)
A30: 5 | B30: 144 | C30: 162.0994 | D30: 97.2944 | E30: 72.0994 | F30: 0.7082 | G30: -35.8972 | H30: 1.4545 | I30: 275.4764 | J30: =MAX(ABS(C10-C30),ABS(D10-D30),ABS(E10-E30),ABS(F10-F30),ABS(G10-G30),ABS(H10-H30),ABS(I10-I30)) -> 4.8268693e-05 | K30: =IF(AND(B30=B10,J30<=0.00051),"SI (redondeo)","NO - revisar datos") -> SI (redondeo)
A31: 6 | B31: 180 | C31: 171.2853 | D31: 95.4761 | E31: 81.2853 | F31: 0.8427 | G31: 16.8545 | H31: -0.1089 | I31: 250.5962 | J31: =MAX(ABS(C11-C31),ABS(D11-D31),ABS(E11-E31),ABS(F11-F31),ABS(G11-G31),ABS(H11-H31),ABS(I11-I31)) -> 4.8557599e-05 | K31: =IF(AND(B31=B11,J31<=0.00051),"SI (redondeo)","NO - revisar datos") -> SI (redondeo)
A32: 7 | B32: 216 | C32: 180.2485 | D32: 103.6832 | E32: 89.7515 | F32: 0.6739 | G32: 64.2446 | H32: -1.5362 | I32: 220.3943 | J32: =MAX(ABS(C12-C32),ABS(D12-D32),ABS(E12-E32),ABS(F12-F32),ABS(G12-G32),ABS(H12-H32),ABS(I12-I32)) -> 4.3813027e-05 | K32: =IF(AND(B32=B12,J32<=0.00051),"SI (redondeo)","NO - revisar datos") -> SI (redondeo)
A33: 8 | B33: 252 | C33: 185.7771 | D33: 120.514 | E33: 84.2229 | F33: 0.2587 | G33: 101.1365 | H33: -2.4948 | I33: 131.1029 | J33: =MAX(ABS(C13-C33),ABS(D13-D33),ABS(E13-E33),ABS(F13-F33),ABS(G13-G33),ABS(H13-H33),ABS(I13-I33)) -> 4.2569159e-05 | K33: =IF(AND(B33=B13,J33<=0.00051),"SI (redondeo)","NO - revisar datos") -> SI (redondeo)
A34: 9 | B34: 288 | C34: 185.7771 | D34: 142.1452 | E34: 84.2229 | F34: -0.2587 | G34: 108.0118 | H34: -2.4948 | I34: -82.3884 | J34: =MAX(ABS(C14-C34),ABS(D14-D34),ABS(E14-E34),ABS(F14-F34),ABS(G14-G34),ABS(H14-H34),ABS(I14-I34)) -> 3.4217e-05 | K34: =IF(AND(B34=B14,J34<=0.00051),"SI (redondeo)","NO - revisar datos") -> SI (redondeo)
A35: 10 | B35: 324 | C35: 180.2485 | D35: 160.3144 | E35: 89.7515 | F35: -0.6739 | G35: 65.0162 | H35: -1.5362 | I35: -338.5332 | J35: =MAX(ABS(C15-C35),ABS(D15-D35),ABS(E15-E35),ABS(F15-F35),ABS(G15-G35),ABS(H15-H35),ABS(I15-I35)) -> 4.7664105e-05 | K35: =IF(AND(B35=B15,J35<=0.00051),"SI (redondeo)","NO - revisar datos") -> SI (redondeo)
A37: Las celdas lilas son valores importados (no formulas). Si cambias a, b, c, n o los θ2, la comparacion deja de aplicar hasta volver a correr la calculadora.

Sheet P2 f) Validacion
A1: INCISO f) - VALIDACION COMPUTACIONAL Y PORCENTAJE DE ERROR
A2: Analitico = formulas de este libro. Simulacion MATLAB (Newton-Raphson + derivacion numerica, 720 pasos) e Inventor (ensamble girado a cada posicion ±0.5°) = valores importados de Resultados_MATLAB/Resultados_Parcial2.xlsx (P2_2_Analisis_Validacion.m), corridos a 30 rpm.
A4: 1. VELOCIDAD DE LA CORRIDA DE MATLAB
A5: Velocidad del motor usada en la simulacion | D5: 30 | E5: rpm | F5: Aqui ω2 es fijo (30 rpm) para comparar contra la misma corrida; no depende de la hoja de Datos.
A6: ω2 de la simulacion | D6: =D5*2*PI()/60 -> 3.1415927 | E6: rad/s
A8: 2. TABLA DE PORCENTAJE DE ERROR POR POSICION (|valor − analitico| / |analitico| × 100)
A9: Pos | B9: θ2 (°) | C9: θ3 (%) | D9: d (%) | E9: ω3 (%) | F9: V_B (%) | G9: α3 (%) | H9: A_B (%) | I9: Max fila (%) | J9: ← simulacion MATLAB
A10: 1 | B10: =B39 -> 0 | C10: =F39 -> 0 | D10: =F53 -> 0 | E10: =F67 -> 0.0011714691 | F10: =F81 -> 0.00098881324 | G10: =F95 -> 0.0021114246 | H10: =F109 -> 0.0010117481 | I10: =MAX(C10:H10) -> 0.0021114246
A11: 2 | B11: =B40 -> 36 | C11: =F40 -> 0 | D11: =F54 -> 0 | E11: =F68 -> 0.0013859817 | F11: =F82 -> 0.0018596457 | G11: =F96 -> 0.00029010026 | H11: =F110 -> 0.00096742575 | I11: =MAX(C11:H11) -> 0.0018596457
A12: 3 | B12: =B41 -> 72 | C12: =F41 -> 0 | D12: =F55 -> 0 | E12: =F69 -> 0.0017161855 | F12: =F83 -> 0.0016209702 | G12: =F97 -> 0.00079618958 | H12: =F111 -> 0.0069307184 | I12: =MAX(C12:H12) -> 0.0069307184
A13: 4 | B13: =B42 -> 108 | C13: =F42 -> 0 | D13: =F56 -> 0 | E13: =F70 -> 0.0017161855 | F13: =F84 -> 0.00079976417 | G13: =F98 -> 0.00079618958 | H13: =F112 -> 0.0013366814 | I13: =MAX(C13:H13) -> 0.0017161855
A14: 5 | B14: =B43 -> 144 | C14: =F43 -> 0 | D14: =F57 -> 0 | E14: =F71 -> 0.0013859817 | F14: =F85 -> 0.00026633944 | G14: =F99 -> 0.00029010421 | H14: =F113 -> 0.0002921794 | I14: =MAX(C14:H14) -> 0.0013859817
A15: 6 | B15: =B44 -> 180 | C15: =F44 -> 0 | D15: =F58 -> 0 | E15: =F72 -> 0.0011714691 | F15: =F86 -> 0.00098881324 | G15: =F100 -> 0.0021114246 | H15: =F114 -> 2.7967281e-05 | I15: =MAX(C15:H15) -> 0.0021114246
A16: 7 | B16: =B45 -> 216 | C16: =F45 -> 0 | D16: =F59 -> 0 | E16: =F73 -> 0.0012133996 | F16: =F87 -> 0.0004485711 | G16: =F101 -> 0.00045835359 | H16: =F115 -> 0.00041184705 | I16: =MAX(C16:H16) -> 0.0012133996
A17: 8 | B17: =B46 -> 252 | C17: =F46 -> 0 | D17: =F60 -> 0 | E17: =F74 -> 0.0013579983 | F17: =F88 -> 0.00094256697 | G17: =F102 -> 0.00065182214 | H17: =F116 -> 0.0017083252 | I17: =MAX(C17:H17) -> 0.0017083252
A18: 9 | B18: =B47 -> 288 | C18: =F47 -> 0 | D18: =F61 -> 0 | E18: =F75 -> 0.0013579983 | F18: =F89 -> 0.0015751083 | G18: =F103 -> 0.00065181984 | H18: =F117 -> 0.0010739491 | I18: =MAX(C18:H18) -> 0.0015751083
A19: 10 | B19: =B48 -> 324 | C19: =F48 -> 0 | D19: =F62 -> 0 | E19: =F76 -> 0.0012133996 | F19: =F90 -> 0.0020801581 | G19: =F104 -> 0.00045835359 | H19: =F118 -> 0.00077964853 | I19: =MAX(C19:H19) -> 0.0020801581
A20: Error maximo, simulacion MATLAB (%): | I20: =MAX(I10:I19) -> 0.0069307184
A21: Pos | B21: θ2 (°) | C21: θ3 (%) | D21: d (%) | E21: ω3 (%) | F21: V_B (%) | G21: α3 (%) | H21: A_B (%) | I21: Max fila (%) | J21: ← ensamble de Inventor
A22: 1 | B22: =B39 -> 0 | C22: =G39 -> 0 | D22: =G53 -> 1.058437e-07 | E22: =G67 -> 0.0011714691 | F22: =G81 -> 0.00098887443 | G22: =G95 -> 0.0021114246 | H22: =G109 -> 0.0010117648 | I22: =MAX(C22:H22) -> 0.0021114246
A23: 2 | B23: =B40 -> 36 | C23: =G40 -> 0 | D23: =G54 -> 1.1575925e-07 | E23: =G68 -> 0.0013859817 | F23: =G82 -> 0.0018596653 | G23: =G96 -> 0.00029010026 | H23: =G110 -> 0.00096744005 | I23: =MAX(C23:H23) -> 0.0018596653
A24: 3 | B24: =B41 -> 72 | C24: =G41 -> 0 | D24: =G55 -> 1.3779465e-07 | E24: =G69 -> 0.0017161855 | F24: =G83 -> 0.0016209785 | G24: =G97 -> 0.00079618958 | H24: =G111 -> 0.0069310071 | I24: =MAX(C24:H24) -> 0.0069310071
A25: 4 | B25: =B42 -> 108 | C25: =G42 -> 0 | D25: =G56 -> 1.6490385e-07 | E25: =G70 -> 0.0017161854 | F25: =G84 -> 0.00079975318 | G25: =G98 -> 0.00079618744 | H25: =G112 -> 0.0013367105 | I25: =MAX(C25:H25) -> 0.0017161854
A26: 5 | B26: =B43 -> 144 | C26: =G43 -> 0 | D26: =G57 -> 1.8313818e-07 | E26: =G71 -> 0.0013859817 | F26: =G85 -> 0.00026639017 | G26: =G99 -> 0.00029008047 | H26: =G113 -> 0.00029219277 | I26: =MAX(C26:H26) -> 0.0013859817
A27: 6 | B27: =B44 -> 180 | C27: =G44 -> 0 | D27: =G58 -> 1.8344469e-07 | E27: =G72 -> 0.0011714691 | F27: =G86 -> 0.00098887474 | G27: =G100 -> 0.002111266 | H27: =G114 -> 2.7990799e-05 | I27: =MAX(C27:H27) -> 0.002111266
A28: 7 | B28: =B45 -> 216 | C28: =G45 -> 0 | D28: =G59 -> 1.680279e-07 | E28: =G73 -> 0.0012133996 | F28: =G87 -> 0.00044857082 | G28: =G101 -> 0.00045834235 | H28: =G115 -> 0.00041182449 | I28: =MAX(C28:H28) -> 0.0012133996
A29: 8 | B29: =B46 -> 252 | C29: =G46 -> 0 | D29: =G60 -> 1.4489913e-07 | E29: =G74 -> 0.0013579983 | F29: =G88 -> 0.00094256496 | G29: =G102 -> 0.00065182676 | H29: =G116 -> 0.0017083379 | I29: =MAX(C29:H29) -> 0.0017083379
A30: 9 | B30: =B47 -> 288 | C30: =G47 -> 0 | D30: =G61 -> 1.2284876e-07 | E30: =G75 -> 0.0013579983 | F30: =G89 -> 0.0015751102 | G30: =G103 -> 0.00065182214 | H30: =G117 -> 0.0010739178 | I30: =MAX(C30:H30) -> 0.0015751102
A31: 10 | B31: =B48 -> 324 | C31: =G48 -> 0 | D31: =G62 -> 1.0867182e-07 | E31: =G76 -> 0.0012133996 | F31: =G90 -> 0.0020801584 | G31: =G104 -> 0.00045833111 | H31: =G118 -> 0.0007796692 | I31: =MAX(C31:H31) -> 0.0020801584
A32: Error maximo, Inventor (%): | I32: =MAX(I22:I31) -> 0.0069310071
A33: =IF(MAX(I20,I32)<0.01,"VALIDADO: el error maximo es "&FIXED(MAX(I20,I32),4)&" % (< 0.01 %). Las diferencias vienen de la derivacion numerica con paso de 0.5°.","Revisar: error maximo "&FIXED(MAX(I20,I32),4)&" %") -> VALIDADO: el error maximo es 0.0069 % (< 0.01 %). Las diferencias vienen de la derivacion numerica con paso de 0.5°.
A35: 3. VALORES DETALLADOS POR VARIABLE (analitico vs simulacion MATLAB vs Inventor)
A37: θ3 (°)
A38: Pos | B38: θ2 (°) | C38: Analitico (Excel) | D38: Simulacion MATLAB | E38: Inventor | F38: Error MATLAB (%) | G38: Error Inventor (%) | H38: Dif. MATLAB | I38: Dif. Inventor
A39: 1 | B39: 0 | C39: =180-DEGREES(ASIN((P2_a*SIN(RADIANS($B39))-P2_c)/P2_b)) -> 171.28526 | D39: 171.28526 | E39: 171.28526 | F39: =IF(C39=0,0,100*ABS(D39-C39)/ABS(C39)) -> 0 | G39: =IF(C39=0,0,100*ABS(E39-C39)/ABS(C39)) -> 0 | H39: =D39-C39 -> 0 | I39: =E39-C39 -> 0
A40: 2 | B40: 36 | C40: =180-DEGREES(ASIN((P2_a*SIN(RADIANS($B40))-P2_c)/P2_b)) -> 162.09936 | D40: 162.09936 | E40: 162.09936 | F40: =IF(C40=0,0,100*ABS(D40-C40)/ABS(C40)) -> 0 | G40: =IF(C40=0,0,100*ABS(E40-C40)/ABS(C40)) -> 0 | H40: =D40-C40 -> 0 | I40: =E40-C40 -> 0
A41: 3 | B41: 72 | C41: =180-DEGREES(ASIN((P2_a*SIN(RADIANS($B41))-P2_c)/P2_b)) -> 156.19099 | D41: 156.19099 | E41: 156.19099 | F41: =IF(C41=0,0,100*ABS(D41-C41)/ABS(C41)) -> 0 | G41: =IF(C41=0,0,100*ABS(E41-C41)/ABS(C41)) -> 0 | H41: =D41-C41 -> 0 | I41: =E41-C41 -> 0
A42: 4 | B42: 108 | C42: =180-DEGREES(ASIN((P2_a*SIN(RADIANS($B42))-P2_c)/P2_b)) -> 156.19099 | D42: 156.19099 | E42: 156.19099 | F42: =IF(C42=0,0,100*ABS(D42-C42)/ABS(C42)) -> 0 | G42: =IF(C42=0,0,100*ABS(E42-C42)/ABS(C42)) -> 0 | H42: =D42-C42 -> 0 | I42: =E42-C42 -> 0
A43: 5 | B43: 144 | C43: =180-DEGREES(ASIN((P2_a*SIN(RADIANS($B43))-P2_c)/P2_b)) -> 162.09936 | D43: 162.09936 | E43: 162.09936 | F43: =IF(C43=0,0,100*ABS(D43-C43)/ABS(C43)) -> 0 | G43: =IF(C43=0,0,100*ABS(E43-C43)/ABS(C43)) -> 0 | H43: =D43-C43 -> 0 | I43: =E43-C43 -> 0
A44: 6 | B44: 180 | C44: =180-DEGREES(ASIN((P2_a*SIN(RADIANS($B44))-P2_c)/P2_b)) -> 171.28526 | D44: 171.28526 | E44: 171.28526 | F44: =IF(C44=0,0,100*ABS(D44-C44)/ABS(C44)) -> 0 | G44: =IF(C44=0,0,100*ABS(E44-C44)/ABS(C44)) -> 0 | H44: =D44-C44 -> 0 | I44: =E44-C44 -> 0
...

Sheet P2 Graficas
A1: GRAFICAS EN FUNCION DEL ANGULO DE ENTRADA θ2
A2: Curva = formulas de la hoja "P2 Curva" (vuelta completa). Puntos = las 10 posiciones del inciso e) y la simulacion de MATLAB del inciso f).
A58: Nota: los puntos de MATLAB son de la corrida a 30 rpm. Si cambias la velocidad en la hoja de Datos, la curva cambia y los puntos de MATLAB no (vuelve a correr P2_2_Analisis_Validacion.m).

Sheet P2 Curva
A1: VUELTA COMPLETA DE LA MANIVELA (cada 0.5°) - datos de las graficas
A2: Formulas vivas con los datos de "P2 a) Datos y Sintesis". Las columnas K a M ubican los 10 puntos del inciso e) y los de la simulacion para las graficas.
A5: θ2 (°) | B5: θ3 (°) | C5: d (mm) | D5: μ (°) | E5: ω3 (rad/s) | F5: V_B (mm/s) | G5: α3 (rad/s²) | H5: A_B (mm/s²) | I5: μ recomendado (°)
A6: 0 | B6: =180-DEGREES(ASIN((P2_a*SIN(RADIANS($A6))-P2_c)/P2_b)) -> 171.28526 | C6: =P2_a*COS(RADIANS($A6))-P2_b*COS(RADIANS(B6)) -> 165.47605 | D6: =90-DEGREES(ASIN(ABS((P2_a*SIN(RADIANS($A6))-P2_c)/P2_b))) -> 81.285258 | E6: =P2_a*P2_w2*COS(RADIANS($A6))/(P2_b*COS(RADIANS(B6))) -> -0.84272739 | F6: =-P2_a*P2_w2*SIN(RADIANS($A6))+P2_b*E6*SIN(RADIANS(B6)) -> -16.854548 | G6: =(P2_a*P2_al2*COS(RADIANS($A6))-P2_a*P2_w2^2*SIN(RADIANS($A6))+P2_b*E6^2*SIN(RADIANS(B6)))/(P2_b*COS(RADIANS(B6))) -> -0.10886127 | H6: =-P2_a*P2_al2*SIN(RADIANS($A6))-P2_a*P2_w2^2*COS(RADIANS($A6))+P2_b*G6*SIN(RADIANS(B6))+P2_b*E6^2*COS(RADIANS(B6)) -> -440.2761 | I6: 45
A7: 0.5 | B7: =180-DEGREES(ASIN((P2_a*SIN(RADIANS($A7))-P2_c)/P2_b)) -> 171.15111 | C7: =P2_a*COS(RADIANS($A7))-P2_b*COS(RADIANS(B7)) -> 165.42754 | D7: =90-DEGREES(ASIN(ABS((P2_a*SIN(RADIANS($A7))-P2_c)/P2_b))) -> 81.151111 | E7: =P2_a*P2_w2*COS(RADIANS($A7))/(P2_b*COS(RADIANS(B7))) -> -0.84300016 | F7: =-P2_a*P2_w2*SIN(RADIANS($A7))+P2_b*E7*SIN(RADIANS(B7)) -> -18.077012 | G7: =(P2_a*P2_al2*COS(RADIANS($A7))-P2_a*P2_w2^2*SIN(RADIANS($A7))+P2_b*E7^2*SIN(RADIANS(B7)))/(P2_b*COS(RADIANS(B7))) -> -0.087523394 | H7: =-P2_a*P2_al2*SIN(RADIANS($A7))-P2_a*P2_w2^2*COS(RADIANS($A7))+P2_b*G7*SIN(RADIANS(B7))+P2_b*E7^2*COS(RADIANS(B7)) -> -439.88938 | I7: 45
A8: 1 | B8: =180-DEGREES(ASIN((P2_a*SIN(RADIANS($A8))-P2_c)/P2_b)) -> 171.01693 | C8: =P2_a*COS(RADIANS($A8))-P2_b*COS(RADIANS(B8)) -> 165.37562 | D8: =90-DEGREES(ASIN(ABS((P2_a*SIN(RADIANS($A8))-P2_c)/P2_b))) -> 81.016926 | E8: =P2_a*P2_w2*COS(RADIANS($A8))/(P2_b*COS(RADIANS(B8))) -> -0.84321361 | F8: =-P2_a*P2_w2*SIN(RADIANS($A8))+P2_b*E8*SIN(RADIANS(B8)) -> -19.298328 | G8: =(P2_a*P2_al2*COS(RADIANS($A8))-P2_a*P2_w2^2*SIN(RADIANS($A8))+P2_b*E8^2*SIN(RADIANS(B8)))/(P2_b*COS(RADIANS(B8))) -> -0.066158439 | H8: =-P2_a*P2_al2*SIN(RADIANS($A8))-P2_a*P2_w2^2*COS(RADIANS($A8))+P2_b*G8*SIN(RADIANS(B8))+P2_b*E8^2*COS(RADIANS(B8)) -> -439.44918 | I8: 45
A9: 1.5 | B9: =180-DEGREES(ASIN((P2_a*SIN(RADIANS($A9))-P2_c)/P2_b)) -> 170.88271 | C9: =P2_a*COS(RADIANS($A9))-P2_b*COS(RADIANS(B9)) -> 165.32032 | D9: =90-DEGREES(ASIN(ABS((P2_a*SIN(RADIANS($A9))-P2_c)/P2_b))) -> 80.882711 | E9: =P2_a*P2_w2*COS(RADIANS($A9))/(P2_b*COS(RADIANS(B9))) -> -0.84336768 | F9: =-P2_a*P2_w2*SIN(RADIANS($A9))+P2_b*E9*SIN(RADIANS(B9)) -> -20.518347 | G9: =(P2_a*P2_al2*COS(RADIANS($A9))-P2_a*P2_w2^2*SIN(RADIANS($A9))+P2_b*E9^2*SIN(RADIANS(B9)))/(P2_b*COS(RADIANS(B9))) -> -0.04476692 | H9: =-P2_a*P2_al2*SIN(RADIANS($A9))-P2_a*P2_w2^2*COS(RADIANS($A9))+P2_b*G9*SIN(RADIANS(B9))+P2_b*E9^2*COS(RADIANS(B9)) -> -438.95548 | I9: 45
A10: 2 | B10: =180-DEGREES(ASIN((P2_a*SIN(RADIANS($A10))-P2_c)/P2_b)) -> 170.74848 | C10: =P2_a*COS(RADIANS($A10))-P2_b*COS(RADIANS(B10)) -> 165.26164 | D10: =90-DEGREES(ASIN(ABS((P2_a*SIN(RADIANS($A10))-P2_c)/P2_b))) -> 80.748477 | E10: =P2_a*P2_w2*COS(RADIANS($A10))/(P2_b*COS(RADIANS(B10))) -> -0.84346229 | F10: =-P2_a*P2_w2*SIN(RADIANS($A10))+P2_b*E10*SIN(RADIANS(B10)) -> -21.73692 | G10: =(P2_a*P2_al2*COS(RADIANS($A10))-P2_a*P2_w2^2*SIN(RADIANS($A10))+P2_b*E10^2*SIN(RADIANS(B10)))/(P2_b*COS(RADIANS(B10))) -> -0.02334935 | H10: =-P2_a*P2_al2*SIN(RADIANS($A10))-P2_a*P2_w2^2*COS(RADIANS($A10))+P2_b*G10*SIN(RADIANS(B10))+P2_b*E10^2*COS(RADIANS(B10)) -> -438.40826 | I10: 45
A11: 2.5 | B11: =180-DEGREES(ASIN((P2_a*SIN(RADIANS($A11))-P2_c)/P2_b)) -> 170.61423 | C11: =P2_a*COS(RADIANS($A11))-P2_b*COS(RADIANS(B11)) -> 165.19956 | D11: =90-DEGREES(ASIN(ABS((P2_a*SIN(RADIANS($A11))-P2_c)/P2_b))) -> 80.614232 | E11: =P2_a*P2_w2*COS(RADIANS($A11))/(P2_b*COS(RADIANS(B11))) -> -0.84349737 | F11: =-P2_a*P2_w2*SIN(RADIANS($A11))+P2_b*E11*SIN(RADIANS(B11)) -> -22.953899 | G11: =(P2_a*P2_al2*COS(RADIANS($A11))-P2_a*P2_w2^2*SIN(RADIANS($A11))+P2_b*E11^2*SIN(RADIANS(B11)))/(P2_b*COS(RADIANS(B11))) -> -0.0019062483 | H11: =-P2_a*P2_al2*SIN(RADIANS($A11))-P2_a*P2_w2^2*COS(RADIANS($A11))+P2_b*G11*SIN(RADIANS(B11))+P2_b*E11^2*COS(RADIANS(B11)) -> -437.80752 | I11: 45
A12: 3 | B12: =180-DEGREES(ASIN((P2_a*SIN(RADIANS($A12))-P2_c)/P2_b)) -> 170.47999 | C12: =P2_a*COS(RADIANS($A12))-P2_b*COS(RADIANS(B12)) -> 165.13412 | D12: =90-DEGREES(ASIN(ABS((P2_a*SIN(RADIANS($A12))-P2_c)/P2_b))) -> 80.479986 | E12: =P2_a*P2_w2*COS(RADIANS($A12))/(P2_b*COS(RADIANS(B12))) -> -0.84347286 | F12: =-P2_a*P2_w2*SIN(RADIANS($A12))+P2_b*E12*SIN(RADIANS(B12)) -> -24.169135 | G12: =(P2_a*P2_al2*COS(RADIANS($A12))-P2_a*P2_w2^2*SIN(RADIANS($A12))+P2_b*E12^2*SIN(RADIANS(B12)))/(P2_b*COS(RADIANS(B12))) -> 0.019561863 | H12: =-P2_a*P2_al2*SIN(RADIANS($A12))-P2_a*P2_w2^2*COS(RADIANS($A12))+P2_b*G12*SIN(RADIANS(B12))+P2_b*E12^2*COS(RADIANS(B12)) -> -437.15326 | I12: 45
A13: 3.5 | B13: =180-DEGREES(ASIN((P2_a*SIN(RADIANS($A13))-P2_c)/P2_b)) -> 170.34575 | C13: =P2_a*COS(RADIANS($A13))-P2_b*COS(RADIANS(B13)) -> 165.06529 | D13: =90-DEGREES(ASIN(ABS((P2_a*SIN(RADIANS($A13))-P2_c)/P2_b))) -> 80.345749 | E13: =P2_a*P2_w2*COS(RADIANS($A13))/(P2_b*COS(RADIANS(B13))) -> -0.84338867 | F13: =-P2_a*P2_w2*SIN(RADIANS($A13))+P2_b*E13*SIN(RADIANS(B13)) -> -25.382479 | G13: =(P2_a*P2_al2*COS(RADIANS($A13))-P2_a*P2_w2^2*SIN(RADIANS($A13))+P2_b*E13^2*SIN(RADIANS(B13)))/(P2_b*COS(RADIANS(B13))) -> 0.041054457 | H13: =-P2_a*P2_al2*SIN(RADIANS($A13))-P2_a*P2_w2^2*COS(RADIANS($A13))+P2_b*G13*SIN(RADIANS(B13))+P2_b*E13^2*COS(RADIANS(B13)) -> -436.44549 | I13: 45
A14: 4 | B14: =180-DEGREES(ASIN((P2_a*SIN(RADIANS($A14))-P2_c)/P2_b)) -> 170.21153 | C14: =P2_a*COS(RADIANS($A14))-P2_b*COS(RADIANS(B14)) -> 164.9931 | D14: =90-DEGREES(ASIN(ABS((P2_a*SIN(RADIANS($A14))-P2_c)/P2_b))) -> 80.211531 | E14: =P2_a*P2_w2*COS(RADIANS($A14))/(P2_b*COS(RADIANS(B14))) -> -0.84324476 | F14: =-P2_a*P2_w2*SIN(RADIANS($A14))+P2_b*E14*SIN(RADIANS(B14)) -> -26.593782 | G14: =(P2_a*P2_al2*COS(RADIANS($A14))-P2_a*P2_w2^2*SIN(RADIANS($A14))+P2_b*E14^2*SIN(RADIANS(B14)))/(P2_b*COS(RADIANS(B14))) -> 0.062571 | H14: =-P2_a*P2_al2*SIN(RADIANS($A14))-P2_a*P2_w2^2*COS(RADIANS($A14))+P2_b*G14*SIN(RADIANS(B14))+P2_b*E14^2*COS(RADIANS(B14)) -> -435.68425 | I14: 45
A15: 4.5 | B15: =180-DEGREES(ASIN((P2_a*SIN(RADIANS($A15))-P2_c)/P2_b)) -> 170.07734 | C15: =P2_a*COS(RADIANS($A15))-P2_b*COS(RADIANS(B15)) -> 164.91755 | D15: =90-DEGREES(ASIN(ABS((P2_a*SIN(RADIANS($A15))-P2_c)/P2_b))) -> 80.077339 | E15: =P2_a*P2_w2*COS(RADIANS($A15))/(P2_b*COS(RADIANS(B15))) -> -0.84304104 | F15: =-P2_a*P2_w2*SIN(RADIANS($A15))+P2_b*E15*SIN(RADIANS(B15)) -> -27.802897 | G15: =(P2_a*P2_al2*COS(RADIANS($A15))-P2_a*P2_w2^2*SIN(RADIANS($A15))+P2_b*E15^2*SIN(RADIANS(B15)))/(P2_b*COS(RADIANS(B15))) -> 0.08411095 | H15: =-P2_a*P2_al2*SIN(RADIANS($A15))-P2_a*P2_w2^2*COS(RADIANS($A15))+P2_b*G15*SIN(RADIANS(B15))+P2_b*E15^2*COS(RADIANS(B15)) -> -434.86955 | I15: 45
A16: 5 | B16: =180-DEGREES(ASIN((P2_a*SIN(RADIANS($A16))-P2_c)/P2_b)) -> 169.94319 | C16: =P2_a*COS(RADIANS($A16))-P2_b*COS(RADIANS(B16)) -> 164.83864 | D16: =90-DEGREES(ASIN(ABS((P2_a*SIN(RADIANS($A16))-P2_c)/P2_b))) -> 79.943185 | E16: =P2_a*P2_w2*COS(RADIANS($A16))/(P2_b*COS(RADIANS(B16))) -> -0.84277745 | F16: =-P2_a*P2_w2*SIN(RADIANS($A16))+P2_b*E16*SIN(RADIANS(B16)) -> -29.009675 | G16: =(P2_a*P2_al2*COS(RADIANS($A16))-P2_a*P2_w2^2*SIN(RADIANS($A16))+P2_b*E16^2*SIN(RADIANS(B16)))/(P2_b*COS(RADIANS(B16))) -> 0.10567376 | H16: =-P2_a*P2_al2*SIN(RADIANS($A16))-P2_a*P2_w2^2*COS(RADIANS($A16))+P2_b*G16*SIN(RADIANS(B16))+P2_b*E16^2*COS(RADIANS(B16)) -> -434.00143 | I16: 45
A17: 5.5 | B17: =180-DEGREES(ASIN((P2_a*SIN(RADIANS($A17))-P2_c)/P2_b)) -> 169.80908 | C17: =P2_a*COS(RADIANS($A17))-P2_b*COS(RADIANS(B17)) -> 164.75639 | D17: =90-DEGREES(ASIN(ABS((P2_a*SIN(RADIANS($A17))-P2_c)/P2_b))) -> 79.809078 | E17: =P2_a*P2_w2*COS(RADIANS($A17))/(P2_b*COS(RADIANS(B17))) -> -0.84245394 | F17: =-P2_a*P2_w2*SIN(RADIANS($A17))+P2_b*E17*SIN(RADIANS(B17)) -> -30.213967 | G17: =(P2_a*P2_al2*COS(RADIANS($A17))-P2_a*P2_w2^2*SIN(RADIANS($A17))+P2_b*E17^2*SIN(RADIANS(B17)))/(P2_b*COS(RADIANS(B17))) -> 0.12725888 | H17: =-P2_a*P2_al2*SIN(RADIANS($A17))-P2_a*P2_w2^2*COS(RADIANS($A17))+P2_b*G17*SIN(RADIANS(B17))+P2_b*E17^2*COS(RADIANS(B17)) -> -433.07994 | I17: 45
... A726: 360 | B726: =180-DEGREES(ASIN((P2_a*SIN(RADIANS($A726))-P2_c)/P2_b)) -> 171.28526 | C726: =P2_a*COS(RADIANS($A726))-P2_b*COS(RADIANS(B726)) -> 165.47605 | D726: =90-DEGREES(ASIN(ABS((P2_a*SIN(RADIANS($A726))-P2_c)/P2_b))) -> 81.285258 | E726: =P2_a*P2_w2*COS(RADIANS($A726))/(P2_b*COS(RADIANS(B726))) -> -0.84272739 | F726: =-P2_a*P2_w2*SIN(RADIANS($A726))+P2_b*E726*SIN(RADIANS(B726)) -> -16.854548 | G726: =(P2_a*P2_al2*COS(RADIANS($A726))-P2_a*P2_w2^2*SIN(RADIANS($A726))+P2_b*E726^2*SIN(RADIANS(B726)))/(P2_b*COS(RADIANS(B726))) -> -0.10886127 | H726: =-P2_a*P2_al2*SIN(RADIANS($A726))-P2_a*P2_w2^2*COS(RADIANS($A726))+P2_b*G726*SIN(RADIANS(B726))+P2_b*E726^2*COS(RADIANS(B726)) -> -440.2761 | I726: 45

Sheet P2 g) Contraste
A1: INCISO g) - CONTRASTE EXPERIMENTAL (modelo fisico vs modelo teorico)
A2: Llena las celdas amarillas con lo que midan en el modelo impreso. Mientras esten vacias, la hoja muestra "—". Las mediciones de rpm vienen del inciso d).
A4: 1. VELOCIDAD ANGULAR DE ENTRADA (dato del inciso d)
A5: Medicion | C5: Valor | D5: Unidad | F5: Notas
A6: Instrumento usado | F6: p. ej. tacometro optico (laser) / video a 60 fps
A7: n medida 1 | D7: rpm | F7: Contar varias vueltas en cada medicion (con carga en la tolva).
A8: n medida 2 | D8: rpm
A9: n medida 3 | D9: rpm
A10: Numero de mediciones | B10: N | C10: =COUNT(C7:C9) -> 0 | D10: -
A11: Promedio | B11: n med | C11: =IF(C10=0,"—",AVERAGE(C7:C9)) -> — | D11: rpm
A12: Desviacion estandar (muestral) | B12: s | C12: =IF(C10<2,"—",STDEV(C7:C9)) -> — | D12: rpm
A13: Coeficiente de variacion | B13: CV | C13: =IF(C10<2,"—",100*C12/C11) -> — | D13: %
A14: Incertidumbre del promedio (95 %) | B14: U95 | C14: =IF(C10<2,"—",TINV(0.05,C10-1)*C12/SQRT(C10)) -> — | D14: rpm | F14: U95 = t(95 %, N−1)·s/√N (t = 4.303 para N = 3)
A15: ω2 medida | B15: ω2 med | C15: =IF(C10=0,"—",P2_sentido*C11*2*PI()/60) -> — | D15: rad/s
A16: ω2 usada en los calculos (diseno) | B16: ω2 teo | C16: =P2_w2 -> 3.1415927 | D16: rad/s
A17: Diferencia medida vs diseno | B17: Δ | C17: =IF(C10=0,"—",100*(C11-P2_n)/P2_n) -> — | D17: % | F17: Si la diferencia es grande, recalcula todo con la velocidad medida: escribe n med en la hoja de Datos (C9).
A19: 2. MAGNITUDES DE SALIDA: TEORICO vs MEDIDO
A20: Magnitud | B20: Teorico | C20: Medido | D20: Unidad | E20: Diferencia (%) | F20: Como se mide
A21: Carrera del bloque (con vernier, en los dos puntos muertos) | B21: =P2_S -> 70.882318 | D21: mm | E21: =IF(ISNUMBER(C21),100*(C21-B21)/B21,"—") -> — | F21: Llevar la manivela a mano a θ2 int y θ2 ext; promediar varias lecturas.
A22: Velocidad maxima del bloque (video / Tracker) | B22: =IF(ISNUMBER(C11),'P2 e) 10 posiciones'!J18*C11/P2_n,'P2 e) 10 posiciones'!J18) -> 119.8018 | D22: mm/s | E22: =IF(ISNUMBER(C22),100*(C22-B22)/B22,"—") -> — | F22: Teorico escalado a la velocidad medida (V ∝ ω2). Pendiente de x(t) en Tracker.
A23: Periodo de un ciclo | B23: =IF(ISNUMBER(C11),60/C11,60/P2_n) -> 2 | D23: s | E23: =IF(ISNUMBER(C23),100*(C23-B23)/B23,"—") -> — | F23: Tiempo entre dos pasos por el mismo punto muerto (video).
A24: Posicion del bloque en θ2 = 90° (desde el punto muerto interior) | B24: ='P2 Curva'!C186-P2_dmin -> 25.080081 | D24: mm | E24: =IF(ISNUMBER(C24),100*(C24-B24)/B24,"—") -> — | F24: Marcar θ2 = 90° en el disco de la manivela y medir la posicion del bloque.
A25: La celda de θ2 = 90° toma d de la hoja P2 Curva (fila de θ2 = 90°).
A27: 3. FUENTES DE DISCREPANCIA - ESTIMACION NUMERICA
A28: Fuente | B28: Dato supuesto | C28: Valor | D28: Unidad | E28: Efecto estimado | F28: Explicacion
A29: Holguras: holgura radial por pasador | B29: e | C29: 0.25 | D29: mm
A30: Holguras: juntas de pasador en serie (O2, A, B) | B30: nj | C30: 3 | D30: -
A31: Juego maximo del bloque (peor caso, 2e por junta) | C31: =2*C29*C30 -> 1.5 | D31: mm | E31: =100*C31/P2_S -> 2.1161836 | F31: % de la carrera. Se nota al invertir el movimiento en los puntos muertos (golpeteo).
A32: Tolerancia de impresion en a, b y c | B32: Δ | C32: 0.2 | D32: mm
A33: Sensibilidad de la carrera a la manivela | B33: ∂S/∂a | C33: =(P2_a+P2_b)/SQRT((P2_a+P2_b)^2-P2_c^2)+(P2_b-P2_a)/SQRT((P2_b-P2_a)^2-P2_c^2) -> 2.0292083 | D33: mm/mm
A34: Sensibilidad de la carrera a la biela | B34: ∂S/∂b | C34: =(P2_a+P2_b)/SQRT((P2_a+P2_b)^2-P2_c^2)-(P2_b-P2_a)/SQRT((P2_b-P2_a)^2-P2_c^2) -> -0.014709564 | D34: mm/mm
A35: Sensibilidad de la carrera al descentrado | B35: ∂S/∂c | C35: =-P2_c/SQRT((P2_a+P2_b)^2-P2_c^2)+P2_c/SQRT((P2_b-P2_a)^2-P2_c^2) -> -0.090084514 | D35: mm/mm
A36: Error de carrera por tolerancias (peor caso) | C36: =C32*(ABS(C33)+ABS(C34)+ABS(C35)) -> 0.42680047 | D36: mm | E36: =100*C36/P2_S -> 0.60212545 | F36: % de la carrera. Casi todo viene de la manivela (∂S/∂a ≈ 2): la carrera es casi 2a.
A37: Friccion: caida de velocidad del motor con carga | B37: Δn | C37: 5 | D37: % | F37: Con friccion el motor se frena en el avance: ω2 deja de ser constante (α2 ≠ 0).
A38: Efecto en velocidades (∝ ω2) | C38: =-C37 -> -5 | D38: %
A39: Efecto en aceleraciones (∝ ω2²) | C39: =100*((1-C37/100)^2-1) -> -9.75 | D39: %
A40: Medicion en video: cuadros por segundo | B40: fps | C40: 60 | D40: cuadros/s
A41: Cuadros por vuelta de la manivela | C41: =C40*60/IF(ISNUMBER(C11),C11,P2_n) -> 120 | D41: cuadros | F41: Mas cuadros por vuelta = mejor resolucion de x(t) y de la velocidad.
A42: Giro de la manivela entre cuadros | C42: =360/C41 -> 3 | D42: °
A43: Masa del bloque con material (estimada) | B43: m | C43: 1.2 | D43: kg
...

Sheet Fila 1
B1: Práctica No.6
B2: Determinación de velocidades mecanismo de cuatro barras método analítico
B3: Escribe los datos en las celdas amarillas; todo lo demás se calcula solo.
B4: Solución | K4: Cálculos intermedios (no editar)
B5: Eslabón 1 | C5: Eslabón 2 | D5: Eslabón 3 | E5: Eslabón 4 | F5: θ2 | G5: ω2 | H5: Rpa | I5: δ | K5: a = Eslabón 2 | L5: =C6 -> 2
B6: 6 | C6: 2 | D6: 7 | E6: 9 | F6: 30 | G6: 10 | H6: 6 | I6: 30 | K6: b = Eslabón 3 | L6: =D6 -> 7
B7: =IF(COUNT($B$6:$I$6)<8,"Faltan datos: llena las 8 celdas amarillas.",IF($L$23,"","R/Para este ángulo de entrada los eslabones no se pueden conectar.")) | K7: c = Eslabón 4 | L7: =E6 -> 9
D8: Posiciones | K8: d = Eslabón 1 | L8: =B6 -> 6
C9: Cruzada | F9: abierta | K9: θ2 en radianes | L9: =RADIANS(F6) -> 0.52359878
C10: RADIANES | D10: GRADOS | F10: RADIANES | G10: GRADOS | K10: K1 = d/a | L10: =L8/L5 -> 3
B11: θ3 | C11: =IFERROR(IF($L$23,2*ATAN((-$L$19+SQRT(MAX(0,$L$22)))/(2*$L$18)),""),"") -> -2.010808 | D11: =IFERROR(IF($L$23,DEGREES(C11),""),"") -> -115.21081 | E11: θ3 | F11: =IFERROR(IF($L$23,2*ATAN((-$L$19-SQRT(MAX(0,$L$22)))/(2*$L$18)),""),"") -> 1.5505024 | G11: =IFERROR(IF($L$23,DEGREES(F11),""),"") -> 88.837241 | K11: K2 = d/c | L11: =L8/L7 -> 0.66666667
B12: θ4 | C12: =IFERROR(IF($L$23,2*ATAN((-$L$16+SQRT(MAX(0,$L$21)))/(2*$L$15)),""),"") -> -2.5073337 | D12: =IFERROR(IF($L$23,DEGREES(C12),""),"") -> -143.65964 | E12: θ4 | F12: =IFERROR(IF($L$23,2*ATAN((-$L$16-SQRT(MAX(0,$L$21)))/(2*$L$15)),""),"") -> 2.0470281 | G12: =IFERROR(IF($L$23,DEGREES(F12),""),"") -> 117.28607 | K12: K3 = (a² − b² + c² + d²)/(2ac) | L12: =(L5^2-L6^2+L7^2+L8^2)/(2*L5*L7) -> 2
B13: μ | C13: =IFERROR(IF($L$23,ACOS(ABS(COS(C12-C11))),""),"") -> 0.49652569 | D13: =IFERROR(IF($L$23,DEGREES(C13),""),"") -> 28.448827 | E13: μ | F13: =IFERROR(IF($L$23,ACOS(ABS(COS(F12-F11))),""),"") -> 0.49652569 | G13: =IFERROR(IF($L$23,DEGREES(F13),""),"") -> 28.448827 | K13: K4 = d/b | L13: =L8/L6 -> 0.85714286
K14: K5 = (c² − d² − a² − b²)/(2ab) | L14: =(L7^2-L8^2-L5^2-L6^2)/(2*L5*L6) -> -0.28571429
C15: GRADOS | K15: A = cosθ2 − K1 − K2·cosθ2 + K3 | L15: =COS(L9)-L10-L11*COS(L9)+L12 -> -0.71132487
B16: θ3 | C16: =IFERROR(IF($L$23,D11+360,""),"") -> 244.78919 | K16: B = −2·sinθ2 | L16: =-2*SIN(L9) -> -1
B17: θ4 | C17: =IFERROR(IF($L$23,D12+360,""),"") -> 216.34036 | K17: C = K1 − (K2 + 1)·cosθ2 + K3 | L17: =L10-(L11+1)*COS(L9)+L12 -> 3.5566243
K18: D = cosθ2 − K1 + K4·cosθ2 + K5 | L18: =COS(L9)-L10+L13*COS(L9)+L14 -> -1.6773814
C19: Velocidades | K19: E = −2·sinθ2 | L19: =-2*SIN(L9) -> -1
D20: Cruzada | F20: abierta | K20: F = K1 + (K4 − 1)·cosθ2 + K5 | L20: =L10+(L13-1)*COS(L9)+L14 -> 2.5905678
D21: RADIANES/s | F21: RADIANES/s | K21: B² − 4AC (para θ4) | L21: =L16^2-4*L15*L17 -> 11.119661
C22: ω3 | D22: =IFERROR(IF($L$23,$L$5*$G$6*SIN(C12-$L$9)/($L$6*SIN(C11-C12)),""),"") -> -0.662352 | E22: ω3 | F22: =IFERROR(IF($L$23,$L$5*$G$6*SIN(F12-$L$9)/($L$6*SIN(F11-F12)),""),"") -> -5.9909657 | K22: E² − 4DF (para θ3) | L22: =L19^2-4*L18*L20 -> 18.381481
C23: ω4 | D23: =IFERROR(IF($L$23,$L$5*$G$6*SIN($L$9-C11)/($L$7*SIN(C12-C11)),""),"") -> -2.6615829 | E23: ω4 | F23: =IFERROR(IF($L$23,$L$5*$G$6*SIN($L$9-F11)/($L$7*SIN(F12-F11)),""),"") -> -3.9917348 | K23: ¿Se conectan? (discriminantes ≥ 0) | L23: =IFERROR(AND(COUNT(B6:I6)=8,L21>=-0.000000001,L22>=-0.000000001),FALSE()) -> TRUE
C24: Vax | D24: =IFERROR(IF($L$23,-$L$5*$G$6*SIN($L$9),""),"") -> -10 | E24: Vax | F24: =IFERROR(IF($L$23,-$L$5*$G$6*SIN($L$9),""),"") -> -10 | K24: θ2 mínimo que conecta (°) | L24: =IFERROR(DEGREES(ACOS(MIN(1,MAX(-1,(L5^2+L8^2-(L6-L7)^2)/(2*L5*L8))))),"") -> 0
C25: Vay | D25: =IFERROR(IF($L$23,$L$5*$G$6*COS($L$9),""),"") -> 17.320508 | E25: Vay | F25: =IFERROR(IF($L$23,$L$5*$G$6*COS($L$9),""),"") -> 17.320508 | K25: θ2 máximo que conecta (°) | L25: =IFERROR(DEGREES(ACOS(MIN(1,MAX(-1,(L5^2+L8^2-(L6+L7)^2)/(2*L5*L8))))),"") -> 180
C26: Vb/a x | D26: =IFERROR(IF($L$23,-$L$6*D22*SIN(C11),""),"") -> -4.1948255 | E26: Vb/a x | F26: =IFERROR(IF($L$23,-$L$6*F22*SIN(F11),""),"") -> 41.928125
C27: Vb/a y | D27: =IFERROR(IF($L$23,$L$6*D22*COS(C11),""),"") -> 1.974902 | E27: Vb/a y | F27: =IFERROR(IF($L$23,$L$6*F22*COS(F11),""),"") -> -0.85100484
C28: Vbx | D28: =IFERROR(IF($L$23,D24+D26,""),"") -> -14.194825 | E28: Vbx | F28: =IFERROR(IF($L$23,F24+F26,""),"") -> 31.928125
C29: Vby | D29: =IFERROR(IF($L$23,D25+D27,""),"") -> 19.29541 | E29: Vby | F29: =IFERROR(IF($L$23,F25+F27,""),"") -> 16.469503
C30: Vp/ax | D30: =IFERROR(IF($L$23,-$H$6*D22*SIN(C11+RADIANS($I$6)),""),"") -> -3.9602369 | E30: Vp/ax | F30: =IFERROR(IF($L$23,-$H$6*F22*SIN(F11+RADIANS($I$6)),""),"") -> 31.488277
C31: Vp/ay | D31: =IFERROR(IF($L$23,$H$6*D22*COS(C11+RADIANS($I$6)),""),"") -> -0.3317978 | E31: Vp/ay | F31: =IFERROR(IF($L$23,$H$6*F22*COS(F11+RADIANS($I$6)),""),"") -> 17.337489
C32: Vpx | D32: =IFERROR(IF($L$23,D24+D30,""),"") -> -13.960237 | E32: Vpx | F32: =IFERROR(IF($L$23,F24+F30,""),"") -> 21.488277
C33: Vpy | D33: =IFERROR(IF($L$23,D25+D31,""),"") -> 16.98871 | E33: Vpy | F33: =IFERROR(IF($L$23,F25+F31,""),"") -> 34.657997
B35: Longitudes en cm, ángulos en grados y ω2 en rad/s. En Velocidades: ω3 y ω4 en rad/s; todas las V en cm/s.
B37: Comprobación: ¿se pueden conectar los eslabones?
B38: Distancia de A a O4 = √(a² + d² − 2·a·d·cos θ2) | F38: =IF(COUNT($B$6:$I$6)<8,"",SQRT($L$5^2+$L$8^2-2*$L$5*$L$8*COS($L$9))) -> 4.3835363 | G38: cm
B39: Mínimo para conectar = |b − c| | F39: =IF(COUNT($B$6:$I$6)<8,"",ABS($L$6-$L$7)) -> 2 | G39: cm
B40: Máximo para conectar = b + c | F40: =IF(COUNT($B$6:$I$6)<8,"",$L$6+$L$7) -> 16 | G40: cm
B41: Valores de θ2 con los que sí se conectan | F41: =IF(COUNT($B$6:$I$6)<8,"",IF(OR((($L$5^2+$L$8^2-($L$6-$L$7)^2)/(2*$L$5*$L$8))<-1,(($L$5^2+$L$8^2-($L$6+$L$7)^2)/(2*$L$5*$L$8))>1),"ninguno (con estas longitudes nunca se conectan)",IF(AND($L$24=0,$L$25=180),"cualquiera (el eslabón 2 da la vuelta completa)","de "&FIXED($L$24,2,TRUE())&"° a "&FIXED($L$25,2,TRUE())&"° y de "&FIXED(360-$L$25,2,TRUE())&"° a "&FIXED(360-$L$24,2,TRUE())&"°"))) -> cualquiera (el eslabón 2 da la vuelta completa)
B42: =IF(COUNT($B$6:$I$6)<8,"",IF($L$23,"R/ Sí se pueden conectar: A–O4 = "&FIXED(F38,3,TRUE())&" cm está entre "&FIXED(F39,3,TRUE())&" y "&FIXED(F40,3,TRUE())&" cm.","R/Para este ángulo de entrada los eslabones no se pueden conectar.")) -> R/ Sí se pueden conectar: A–O4 = 4.384 cm está entre 2.000 y 16.000 cm.

Sheet Fila 2
B1: Práctica No.6
B2: Determinación de velocidades mecanismo de cuatro barras método analítico
B3: Escribe los datos en las celdas amarillas; todo lo demás se calcula solo.
B4: Solución | K4: Cálculos intermedios (no editar)
B5: Eslabón 1 | C5: Eslabón 2 | D5: Eslabón 3 | E5: Eslabón 4 | F5: θ2 | G5: ω2 | H5: Rpa | I5: δ | K5: a = Eslabón 2 | L5: =C6 -> 10
B6: 3 | C6: 10 | D6: 6 | E6: 8 | F6: 45 | G6: -15 | H6: 10 | I6: 80 | K6: b = Eslabón 3 | L6: =D6 -> 6
B7: =IF(COUNT($B$6:$I$6)<8,"Faltan datos: llena las 8 celdas amarillas.",IF($L$23,"","R/Para este ángulo de entrada los eslabones no se pueden conectar.")) | K7: c = Eslabón 4 | L7: =E6 -> 8
D8: Posiciones | K8: d = Eslabón 1 | L8: =B6 -> 3
C9: Cruzada | F9: abierta | K9: θ2 en radianes | L9: =RADIANS(F6) -> 0.78539816
C10: RADIANES | D10: GRADOS | F10: RADIANES | G10: GRADOS | K10: K1 = d/a | L10: =L8/L5 -> 0.3
B11: θ3 | C11: =IFERROR(IF($L$23,2*ATAN((-$L$19+SQRT(MAX(0,$L$22)))/(2*$L$18)),""),"") -> 3.0241472 | D11: =IFERROR(IF($L$23,DEGREES(C11),""),"") -> 173.27087 | E11: θ3 | F11: =IFERROR(IF($L$23,2*ATAN((-$L$19-SQRT(MAX(0,$L$22)))/(2*$L$18)),""),"") -> -0.92732889 | G11: =IFERROR(IF($L$23,DEGREES(F11),""),"") -> -53.132032 | K11: K2 = d/c | L11: =L8/L7 -> 0.375
B12: θ4 | C12: =IFERROR(IF($L$23,2*ATAN((-$L$16+SQRT(MAX(0,$L$21)))/(2*$L$15)),""),"") -> 1.8089923 | D12: =IFERROR(IF($L$23,DEGREES(C12),""),"") -> 103.64762 | E12: θ4 | F12: =IFERROR(IF($L$23,2*ATAN((-$L$16-SQRT(MAX(0,$L$21)))/(2*$L$15)),""),"") -> 0.28782599 | G12: =IFERROR(IF($L$23,DEGREES(F12),""),"") -> 16.491215 | K12: K3 = (a² − b² + c² + d²)/(2ac) | L12: =(L5^2-L6^2+L7^2+L8^2)/(2*L5*L7) -> 0.85625
B13: μ | C13: =IFERROR(IF($L$23,ACOS(ABS(COS(C12-C11))),""),"") -> 1.2151549 | D13: =IFERROR(IF($L$23,DEGREES(C13),""),"") -> 69.623246 | E13: μ | F13: =IFERROR(IF($L$23,ACOS(ABS(COS(F12-F11))),""),"") -> 1.2151549 | G13: =IFERROR(IF($L$23,DEGREES(F13),""),"") -> 69.623246 | K13: K4 = d/b | L13: =L8/L6 -> 0.5
K14: K5 = (c² − d² − a² − b²)/(2ab) | L14: =(L7^2-L8^2-L5^2-L6^2)/(2*L5*L6) -> -0.675
C15: GRADOS | K15: A = cosθ2 − K1 − K2·cosθ2 + K3 | L15: =COS(L9)-L10-L11*COS(L9)+L12 -> 0.99819174
B16: θ3 | C16: =IFERROR(IF($L$23,D11+360,""),"") -> 533.27087 | K16: B = −2·sinθ2 | L16: =-2*SIN(L9) -> -1.4142136
B17: θ4 | C17: =IFERROR(IF($L$23,D12+360,""),"") -> 463.64762 | K17: C = K1 − (K2 + 1)·cosθ2 + K3 | L17: =L10-(L11+1)*COS(L9)+L12 -> 0.18397818
K18: D = cosθ2 − K1 + K4·cosθ2 + K5 | L18: =COS(L9)-L10+L13*COS(L9)+L14 -> 0.085660172
C19: Velocidades | K19: E = −2·sinθ2 | L19: =-2*SIN(L9) -> -1.4142136
D20: Cruzada | F20: abierta | K20: F = K1 + (K4 − 1)·cosθ2 + K5 | L20: =L10+(L13-1)*COS(L9)+L14 -> -0.72855339
D21: RADIANES/s | F21: RADIANES/s | K21: B² − 4AC (para θ4) | L21: =L16^2-4*L15*L17 -> 1.265418
